<?xml version="1.0" encoding="utf-8"?>
<robot name="gripper">

  <joint name="base_joint" type="fixed">
    <origin xyz="0.0 0.0 0.1134" rpy="0 0 1.57"/>
    <parent link="wrist3_link"/>
    <child link="hand_hand"/>
  </joint>


  <!-- Main hand link -->
  <link name="hand_hand">
    <visual>
      <geometry>
        <mesh filename="package://fairino_description/meshes/gripper/hand.dae"/>
      </geometry>
    </visual>
    <collision>
      <origin xyz="0 0 0.04" rpy="0 1.57079633 1.57079633"/>
      <geometry>
        <cylinder radius="0.04" length="0.1"/>
      </geometry>
    </collision>
    <collision>
      <origin xyz="0 -0.05 0.04" rpy="0 0 0"/>
      <geometry>
        <sphere radius="0.04"/>
      </geometry>
    </collision>
    <collision>
      <origin xyz="0 0.05 0.04" rpy="0 0 0"/>
      <geometry>
        <sphere radius="0.04"/>
      </geometry>
    </collision>
    <collision>
      <origin xyz="0 0 0.1" rpy="0 1.57079633 1.57079633"/>
      <geometry>
        <cylinder radius="0.02" length="0.1"/>
      </geometry>
    </collision>
    <collision>
      <origin xyz="0 -0.05 0.1" rpy="0 0 0"/>
      <geometry>
        <sphere radius="0.02"/>
      </geometry>
    </collision>
    <collision>
      <origin xyz="0 0.05 0.1" rpy="0 0 0"/>
      <geometry>
        <sphere radius="0.02"/>
      </geometry>
    </collision>
  </link>

  <!-- Hand TCP frame -->
  <link name="hand_hand_tcp"/>
  <joint name="hand_tcp_joint" type="fixed">
    <origin xyz="0 0 0.1034" rpy="0 0 0"/>
    <parent link="hand_hand"/>
    <child link="hand_hand_tcp"/>
  </joint>

  <!-- Left Finger -->
  <link name="hand_leftfinger">
    <visual>
      <geometry>
        <mesh filename="package://fairino_description/meshes/gripper/finger.dae"/>
      </geometry>
    </visual>
  </link>

  <!-- Right Finger -->
  <link name="hand_rightfinger">
    <visual>
      <origin xyz="0 0 0" rpy="0 0 3.14159265"/>
      <geometry>
        <mesh filename="package://fairino_description/meshes/gripper/finger.dae"/>
      </geometry>
    </visual>
  </link>

  <!-- Finger Joints -->
  <joint name="hand_finger_joint1" type="prismatic">
    <parent link="hand_hand"/>
    <child link="hand_leftfinger"/>
    <origin xyz="0 0 0.0584" rpy="0 0 0"/>
    <axis xyz="0 1 0"/>
    <limit effort="20" lower="0.0" upper="0.04" velocity="0.2"/>
  </joint>
  <joint name="hand_finger_joint2" type="prismatic">
    <parent link="hand_hand"/>
    <child link="hand_rightfinger"/>
    <origin xyz="0 0 0.0584" rpy="0 0 0"/>
    <axis xyz="0 -1 0"/>
    <limit effort="20" lower="0.0" upper="0.04" velocity="0.2"/>
    <mimic joint="hand_finger_joint1"/>
  </joint>
  
</robot>